<?xml version="1.0" encoding="utf-8" ?>
<!-- =================================================================================== -->
<!-- |    This document was autogenerated by xacro from /home/lys/catkin_ws/src/crawler_crane/crawler_crane_description/urdf/crawler_crane.urdf.xacro | -->
<!-- |    EDITING THIS FILE BY HAND IS NOT RECOMMENDED                                 | -->
<!-- =================================================================================== -->
<robot name="crawler_crane" xmlns:xacro="http://www.ros.org/wiki/xacro">
    <material name="black">
        <color rgba="0.0 0.0 0.0 1.0" />
    </material>
    <material name="blue">
        <color rgba="0.0 0.0 0.8 1.0" />
    </material>
    <material name="green">
        <color rgba="0.0 0.8 0.0 1.0" />
    </material>
    <material name="grey">
        <color rgba="0.2 0.2 0.2 1.0" />
    </material>
    <material name="orange">
        <color rgba="1.0 0.423529411765 0.0392156862745 1.0" />
    </material>
    <material name="brown">
        <color rgba="0.870588235294 0.811764705882 0.764705882353 1.0" />
    </material>
    <material name="red">
        <color rgba="0.8 0.0 0.0 1.0" />
    </material>
    <material name="white">
        <color rgba="1.0 1.0 1.0 1.0" />
    </material>
    <!--===============================================================================================-->
    <!-- BASE-FOOTPRINT -->
    <!-- base_footprint is a fictitious link(frame) that is on the ground right below base_link origin -->
    <link name="base_footprint">
        
<inertial>
            <mass value="0.0001" />
            <origin xyz="0 0 0" />
            <inertia ixx="0.0001" ixy="0.0" ixz="0.0" iyy="0.0001" iyz="0.0" izz="0.0001" />
        </inertial>

        <visual>
            <origin rpy="0 0 0" xyz="0 0 0" />
            <geometry>
                <box size="0.001 0.001 0.001" />
            </geometry>
        </visual>
    </link>
    <gazebo reference="base_footprint">
        <material>Gazebo/Blue</material>
    </gazebo>
    <joint name="base_footprint_joint" type="fixed">
        <origin rpy="0 0 0" xyz="0 0 1.05" />
        <parent link="base_footprint" />
        <child link="bottom_link" />
    </joint>
    <!-- BOTTOM-->
    <link name="bottom_link">
        
<inertial>
            <mass value="1750.0" />
            <inertia ixx="6337.91666667" ixy="0" ixz="0" iyy="11949.5833333" iyz="0" izz="5964.58333333" />
        </inertial>

        <!-- the crawlerM is placed on the wheels -->
        <visual>
            <origin rpy="0 0 0" xyz="0 0 0" />
            <geometry>
                <box size="6.5 6.3 1.1" />
            </geometry>
            <material name="White" />
        </visual>
        <collision>
            <origin rpy="0 0 0 " xyz="0 0 0" />
            <geometry>
                <box size="6.5 6.3 1.1" />
            </geometry>
        </collision>
        <!-- L-crawler -->
        <visual>
            <origin rpy="0 0 0" xyz="0 3.75 -0.25" />
            <geometry>
                <box size="10.385 1.2 1.6" />
            </geometry>
            <material name="red" />
        </visual>
        <collision>
            <origin rpy="0 0 0" xyz="0 3.75 -0.25" />
            <geometry>
                <box size="10.385 1.2 1.6" />
            </geometry>
        </collision>
        <!-- R-crawler -->
        <visual>
            <origin rpy="0 0 0" xyz="0 -3.75 -0.25" />
            <geometry>
                <box size="10.385 1.2 1.6" />
            </geometry>
            <material name="red" />
        </visual>
        <collision>
            <origin rpy="0 0 0" xyz="0 -3.75 -0.25" />
            <geometry>
                <box size="10.385 1.2 1.6" />
            </geometry>
        </collision>
        <!-- slewingRing -->
        <visual>
            <origin rpy="0 0 0" xyz="0 0 0.8" />
            <geometry>
                <cylinder length="0.5" radius="1.5" />
            </geometry>
            <material name="White" />
        </visual>
        <collision>
            <origin rpy="0 0 0" xyz="0 0 0.8" />
            <geometry>
                <cylinder length="0.5" radius="1.5" />
            </geometry>
        </collision>
    </link>
    <!-- lr: left, right -->
    <link name="wheel_right_link">
        <visual>
            <origin rpy="1.57079632679 0  0 " xyz="0 0 0" />
            <geometry>
                <cylinder length="0.12" radius="0.8" />
            </geometry>
            <material name="Black" />
        </visual>
        <collision>
            <origin rpy="1.57079632679 0 0 " xyz="0 0 0" />
            <geometry>
                <cylinder length="0.12" radius="0.8" />
            </geometry>
        </collision>
        
<inertial>
            <mass value="2770000.0" />
            <inertia ixx="775600.0" ixy="0" ixz="0" iyy="775600.0" iyz="0" izz="886400.0" />
        </inertial>

        <!-- the crawlerM is placed on the wheels -->
    </link>
    <gazebo reference="wheel_right_link">
        <material>Gazebo/Black</material>
    </gazebo>
    <joint name="chassis_to_wheel_right_joint" type="continuous">
        <parent link="bottom_link" />
        <child link="wheel_right_link" />
        <origin rpy="0 0 0" xyz="0 4.35 -0.25" />
        <axis rpy="0 0 0" xyz="0 1 0" />
    </joint>
    <!-- Transmission is important to link the joints and the controller -->
    <transmission name="wheel_right_joint_trans">
        <type>transmission_interface/SimpleTransmission</type>
        <joint name="chassis_to_wheel_right_joint" />
        <actuator name="wheel_right_joint_motor">
            <hardwareInterface>EffortJointInterface</hardwareInterface>
            <mechanicalReduction>1</mechanicalReduction>
        </actuator>
    </transmission>
    <!-- lr: left, right -->
    <link name="wheel_left_link">
        <visual>
            <origin rpy="1.57079632679 0  0 " xyz="0 0 0" />
            <geometry>
                <cylinder length="0.12" radius="0.8" />
            </geometry>
            <material name="Black" />
        </visual>
        <collision>
            <origin rpy="1.57079632679 0 0 " xyz="0 0 0" />
            <geometry>
                <cylinder length="0.12" radius="0.8" />
            </geometry>
        </collision>
        
<inertial>
            <mass value="2770000.0" />
            <inertia ixx="775600.0" ixy="0" ixz="0" iyy="775600.0" iyz="0" izz="886400.0" />
        </inertial>

        <!-- the crawlerM is placed on the wheels -->
    </link>
    <gazebo reference="wheel_left_link">
        <material>Gazebo/Black</material>
    </gazebo>
    <joint name="chassis_to_wheel_left_joint" type="continuous">
        <parent link="bottom_link" />
        <child link="wheel_left_link" />
        <origin rpy="0 0 0" xyz="0 -4.35 -0.25" />
        <axis rpy="0 0 0" xyz="0 1 0" />
    </joint>
    <!-- Transmission is important to link the joints and the controller -->
    <transmission name="wheel_left_joint_trans">
        <type>transmission_interface/SimpleTransmission</type>
        <joint name="chassis_to_wheel_left_joint" />
        <actuator name="wheel_left_joint_motor">
            <hardwareInterface>EffortJointInterface</hardwareInterface>
            <mechanicalReduction>1</mechanicalReduction>
        </actuator>
    </transmission>
    <!-- superStructure Definitions -->
    <joint name="superStructure_joint" type="continuous">
        <origin rpy="0 0 0" xyz="0 0 1.05" />
        <!-- on the top of slewingRing -->
        <axis rpy="0 0 0" xyz="0 0 1" />
        <limit effort="1000000000000000000000000000" velocity="1.57079632679" />
        <parent link="bottom_link" />
        <child link="superStructure_link" />
    </joint>
    <link name="superStructure_link">
        
<inertial>
            <mass value="3300.0" />
            <inertia ixx="23166.0" ixy="0" ixz="0" iyy="24431.0" iyz="0" izz="3047.0" />
        </inertial>

        <visual>
            <origin rpy="0 0 0" xyz="-3.0 0 0.9" />
            <geometry>
                <box size="9.0 2.8 1.8" />
            </geometry>
            <material name="White" />
        </visual>
        <collision>
            <origin rpy="0 0 0 " xyz="-3.0 0 0.9" />
            <geometry>
                <box size="9.0 2.8 1.8" />
            </geometry>
        </collision>
    </link>
    <!-- lr: left, right -->
    <link name="counterWeight_right_link">
        <visual>
            <origin rpy="0 0  0" xyz="0 0 1.55" />
            <geometry>
                <box size="2.495 1.6 3.1" />
            </geometry>
            <material name="red" />
        </visual>
        <collision>
            <origin rpy="0 0 0" xyz="0 0 1.55" />
            <geometry>
                <box size="2.495 1.6 3.1" />
            </geometry>
        </collision>
        
<inertial>
            <mass value="6.75" />
            <inertia ixx="8.9072015625" ixy="0" ixz="0" iyy="4.9415765625" iyz="0" izz="6.845625" />
        </inertial>

    </link>
    <gazebo reference="counterWeight_right_link">
        <material>Gazebo/Red</material>
    </gazebo>
    <joint name="superStructure_to_counterWeight_right_joint" type="fixed">
        <parent link="superStructure_link" />
        <child link="counterWeight_right_link" />
        <origin rpy="0 0 0" xyz="-6.75 2.2 0" />
    </joint>
    <!-- lr: left, right -->
    <link name="counterWeight_left_link">
        <visual>
            <origin rpy="0 0  0" xyz="0 0 1.55" />
            <geometry>
                <box size="2.495 1.6 3.1" />
            </geometry>
            <material name="red" />
        </visual>
        <collision>
            <origin rpy="0 0 0" xyz="0 0 1.55" />
            <geometry>
                <box size="2.495 1.6 3.1" />
            </geometry>
        </collision>
        
<inertial>
            <mass value="6.75" />
            <inertia ixx="8.9072015625" ixy="0" ixz="0" iyy="4.9415765625" iyz="0" izz="6.845625" />
        </inertial>

    </link>
    <gazebo reference="counterWeight_left_link">
        <material>Gazebo/Red</material>
    </gazebo>
    <joint name="superStructure_to_counterWeight_left_joint" type="fixed">
        <parent link="superStructure_link" />
        <child link="counterWeight_left_link" />
        <origin rpy="0 0 0" xyz="-6.75 -2.2 0" />
    </joint>
    <!-- luffing: boom joint -->
    <joint name="boom_joint" type="revolute">
        <origin rpy="0 0 0" xyz="1.5 0 0.49" />
        <axis xyz="0 -1 0" />
        <limit effort="1000000000000000000000000000" lower="0.6" upper="1.57079632679" velocity="1.57" />
        <parent link="superStructure_link" />
        <child link="boom_link" />
    </joint>
    <link name="boom_link">
        
<inertial>
            <mass value="232.0" />
            <inertia ixx="60740.6933333" ixy="0" ixz="0" iyy="60780.9066667" iyz="0" izz="262.933333333" />
        </inertial>

        <visual>
            <plugin filename="libsome_visual_plugin.so" name="some_visual_plugin" />
            <origin rpy="0 0 0" xyz="0 0 0" />
            <geometry>
                <!--<box size="${boomL} ${boomW} ${boomH}" />-->
                <mesh filename="package://crawler_crane_description/meshes/boom.dae" />
            </geometry>
            <material name="red" />
        </visual>
        <collision>
            <origin rpy="0 0 0" xyz="28.0 0 0" />
            <geometry>
                <box size="56.0 2.8 2.4" />
            </geometry>
        </collision>
    </link>
    <joint name="rope_joint" type="revolute">
        <origin rpy="0 0 0" xyz="56.0 0 -1.66" />
        <axis xyz="0 -1 0" />
        <limit effort="1000000000000000000000000000" lower="-3.14159265359" upper="3.14159265359" velocity="1.57" />
        <mimic joint="boom_joint" multiplier="-1.0" offset="0" />
        <parent link="boom_link" />
        <child link="rope_link" />
    </joint>
    <link name="rope_link">
        
<inertial>
            <mass value="150.0" />
            <inertia ixx="31250.125" ixy="0" ixz="0" iyy="0.25" iyz="0" izz="31250.125" />
        </inertial>

        <!--hookBlock Mass is placed here -->
        <visual>
            <origin rpy="0 0 0" xyz="0 0 -2.5" />
            <geometry>
                <box size="0.1 0.1 5" />
            </geometry>
        </visual>
    </link>
    <joint name="hook_block_joint" type="prismatic">
        <origin rpy="0 0 0" xyz="0 0 0" />
        <axis xyz="0 0 -1" />
        <limit effort="1000000000000000000000000000" lower="0" upper="84.0" velocity="2.0" />
        <parent link="rope_link" />
        <child link="hook_block_link" />
    </joint>
    <link name="hook_block_link">
        
<inertial>
            <mass value="0.03" />
            <inertia ixx="0.027378" ixy="0" ixz="0" iyy="0.027378" iyz="0" izz="0.027378" />
        </inertial>

        <visual>
            <origin rpy="0 0 0" xyz="0 0 0" />
            <geometry>
                <!--<box size="${size} ${size} ${size}" />-->
                <mesh filename="package://crawler_crane_description/meshes/hookblock.dae" />
            </geometry>
            <material name="red" />
        </visual>
        <collision>
            <origin rpy="0 0 0" xyz="0 0 1.17" />
            <geometry>
                <box size="0.7722 2.34 2.34" />
            </geometry>
        </collision>
    </link>
    <joint name="hook_joint" type="revolute">
        <origin rpy="0 0 0" xyz="0 0 -4.11" />
        <axis xyz="0 0 1" />
        <limit effort="1000000000000000000000000000" lower="-3.14159265359" upper="3.14159265359" velocity="1.57" />
        <parent link="hook_block_link" />
        <child link="hook_link" />
    </joint>
    <link name="hook_link">
        
<inertial>
            <mass value="0.001" />
            <inertia ixx="0.00052215" ixy="0" ixz="0" iyy="0.000594408333333" iyz="0" izz="0.000594408333333" />
        </inertial>

        <visual>
            <origin rpy="0 0 0" xyz="0 0 0" />
            <geometry>
                <mesh filename="package://crawler_crane_description/meshes/hook.dae" />
            </geometry>
            <material name="red" />
        </visual>
        <collision>
            <origin rpy="0 0 0" xyz="0 0 0.885" />
            <geometry>
                <box size="1.77 2 1.77" />
            </geometry>
        </collision>
    </link>
    <transmission name="tran1">
        <type>transmission_interface/SimpleTransmission</type>
        <joint name="superStructure_joint">
            <hardwareInterface>PositionJointInterface</hardwareInterface>
            <hardwareInterface>VelocityJointInterface</hardwareInterface>
            <hardwareInterface>EffortJointInterface</hardwareInterface>
        </joint>
        <actuator name="motor1">
            <hardwareInterface>VelocityJointInterface</hardwareInterface>
            <mechanicalReduction>1</mechanicalReduction>
        </actuator>
    </transmission>
    <transmission name="tran1">
        <type>transmission_interface/SimpleTransmission</type>
        <joint name="boom_joint">
            <hardwareInterface>PositionJointInterface</hardwareInterface>
            <hardwareInterface>VelocityJointInterface</hardwareInterface>
            <hardwareInterface>EffortJointInterface</hardwareInterface>
        </joint>
        <actuator name="motor1">
            <hardwareInterface>VelocityJointInterface</hardwareInterface>
            <mechanicalReduction>1</mechanicalReduction>
        </actuator>
    </transmission>
    <transmission name="tran1">
        <type>transmission_interface/SimpleTransmission</type>
        <joint name="rope_joint">
            <hardwareInterface>PositionJointInterface</hardwareInterface>
            <hardwareInterface>VelocityJointInterface</hardwareInterface>
            <hardwareInterface>EffortJointInterface</hardwareInterface>
        </joint>
        <actuator name="motor1">
            <hardwareInterface>VelocityJointInterface</hardwareInterface>
            <mechanicalReduction>1</mechanicalReduction>
        </actuator>
    </transmission>
    <transmission name="tran1">
        <type>transmission_interface/SimpleTransmission</type>
        <joint name="hook_block_joint">
            <hardwareInterface>PositionJointInterface</hardwareInterface>
            <hardwareInterface>VelocityJointInterface</hardwareInterface>
            <hardwareInterface>EffortJointInterface</hardwareInterface>
        </joint>
        <actuator name="motor1">
            <hardwareInterface>VelocityJointInterface</hardwareInterface>
            <mechanicalReduction>1</mechanicalReduction>
        </actuator>
    </transmission>
    <transmission name="tran1">
        <type>transmission_interface/SimpleTransmission</type>
        <joint name="hook_joint">
            <hardwareInterface>PositionJointInterface</hardwareInterface>
            <hardwareInterface>VelocityJointInterface</hardwareInterface>
            <hardwareInterface>EffortJointInterface</hardwareInterface>
        </joint>
        <actuator name="motor1">
            <hardwareInterface>VelocityJointInterface</hardwareInterface>
            <mechanicalReduction>1</mechanicalReduction>
        </actuator>
    </transmission>
    <gazebo>
        <!-- Differential drive controller  -->
        <plugin filename="libgazebo_ros_diff_drive.so" name="differential_drive_controller">
            <rosDebugLevel>Debug</rosDebugLevel>
            <publishWheelTF>true</publishWheelTF>
            <robotNamespace>/</robotNamespace>
            <publishTf>1</publishTf>
            <publishWheelJointState>true</publishWheelJointState>
            <alwaysOn>true</alwaysOn>
            <legacyMode>true</legacyMode>
            <updateRate>100.0</updateRate>
            <leftJoint>chassis_to_wheel_left_joint</leftJoint>
            <rightJoint>chassis_to_wheel_right_joint</rightJoint>
            <wheelSeparation>4.35</wheelSeparation>
            <wheelDiameter>1.6</wheelDiameter>
            <broadcastTF>1</broadcastTF>
            <wheelTorque>30000000000000000000000000000000000000000</wheelTorque>
            <wheelAcceleration>1.8</wheelAcceleration>
            <commandTopic>cmd_vel</commandTopic>
            <odometryFrame>odom</odometryFrame>
            <odometryTopic>odom</odometryTopic>
            <robotBaseFrame>base_footprint</robotBaseFrame>
        </plugin>
        <!-- ros_control plugin -->
        <plugin filename="libgazebo_ros_control.so" name="gazebo_ros_control">
            <robotNamespace>/</robotNamespace>
        </plugin>
        <!-- gazebo_mimic_joint plugin -->
        <plugin filename="libroboticsgroup_gazebo_mimic_joint_plugin.so" name="gazebo_mimic_joint">
            <rosDebugLevel>Debug</rosDebugLevel>
            <robotNamespace>/</robotNamespace>
            <joint>boom_joint</joint>
            <mimicJoint>rope_joint</mimicJoint>
            <multiplier>-1</multiplier>
            <maxEffort>1000000000000000000000000000</maxEffort>
        </plugin>
    </gazebo>
    <joint name="velodyne2_base_mount_joint" type="fixed">
        <origin rpy="0 0 0" xyz="4.5 1.68 9.0" />
        <parent link="superStructure_link" />
        <child link="velodyne2_base_link" />
    </joint>
    <link name="velodyne2_base_link">
        
<inertial>
            <mass value="1.0" />
            <origin xyz="0 0 0.07212" />
            <inertia ixx="0.002188947025" ixy="0" ixz="0" iyy="0.002188947025" iyz="0" izz="0.00091036445" />
        </inertial>

        <visual>
            <geometry>
                <mesh filename="package://velodyne_description/meshes/HDL32E_base.dae" />
            </geometry>
        </visual>
        <collision>
            <origin rpy="0 0 0" xyz="0 0 0.07212" />
            <geometry>
                <cylinder length="0.14424" radius="0.04267" />
            </geometry>
        </collision>
    </link>
    <joint name="velodyne2_base_scan_joint" type="fixed">
        <origin rpy="0 0 0" xyz="0 0 0.09081" />
        <parent link="velodyne2_base_link" />
        <child link="velodyne2" />
    </joint>
    <link name="velodyne2">
        
<inertial>
            <mass value="0.01" />
            <origin xyz="0 0 0" />
            <inertia ixx="1e-7" ixy="0" ixz="0" iyy="1e-7" iyz="0" izz="1e-7" />
        </inertial>

        <visual>
            <origin rpy="0 0 0" xyz="0 0 -0.09081" />
            <geometry>
                <mesh filename="package://velodyne_description/meshes/HDL32E_scan.dae" />
            </geometry>
        </visual>
    </link>
    <!-- Gazebo requires the velodyne_gazebo_plugins package -->
    <gazebo reference="velodyne2">
        <sensor name="velodyne2-HDL32E" type="ray">
            <pose>0 0 0 0 0 0</pose>
            <visualize>false</visualize>
            <update_rate>10</update_rate>
            <ray>
                <scan>
                    <horizontal>
                        <samples>220</samples>
                        <resolution>1</resolution>
                        <min_angle>-3.14159265359</min_angle>
                        <max_angle>3.14159265359</max_angle>
                    </horizontal>
                    <vertical>
                        <samples>32</samples>
                        <resolution>1</resolution>
                        <min_angle>-0.535292481587</min_angle>
                        <max_angle>0.186226631188</max_angle>
                    </vertical>
                </scan>
                <range>
                    <min>0.3</min>
                    <max>131.0</max>
                    <resolution>0.001</resolution>
                </range>
                <noise>
                    <type>gaussian</type>
                    <mean>0.0</mean>
                    <stddev>0.0</stddev>
                </noise>
            </ray>
            <plugin filename="libgazebo_ros_velodyne_laser.so" name="gazebo_ros_laser_controller">
                <topicName>/velodyne_points2</topicName>
                <frameName>velodyne2</frameName>
                <min_range>0.9</min_range>
                <max_range>130.0</max_range>
                <gaussianNoise>0.008</gaussianNoise>
            </plugin>
        </sensor>
    </gazebo>
    <transmission name="trans_chassis_to_wheel_right_joint">
        <type>transmission_interface/SimpleTransmission</type>
        <joint name="chassis_to_wheel_right_joint">
            <hardwareInterface>hardware_interface/EffortJointInterface</hardwareInterface>
        </joint>
        <actuator name="chassis_to_wheel_right_joint_motor">
            <hardwareInterface>hardware_interface/EffortJointInterface</hardwareInterface>
            <mechanicalReduction>1</mechanicalReduction>
        </actuator>
    </transmission>
    <transmission name="trans_chassis_to_wheel_left_joint">
        <type>transmission_interface/SimpleTransmission</type>
        <joint name="chassis_to_wheel_left_joint">
            <hardwareInterface>hardware_interface/EffortJointInterface</hardwareInterface>
        </joint>
        <actuator name="chassis_to_wheel_left_joint_motor">
            <hardwareInterface>hardware_interface/EffortJointInterface</hardwareInterface>
            <mechanicalReduction>1</mechanicalReduction>
        </actuator>
    </transmission>
    <transmission name="trans_superStructure_joint">
        <type>transmission_interface/SimpleTransmission</type>
        <joint name="superStructure_joint">
            <hardwareInterface>hardware_interface/EffortJointInterface</hardwareInterface>
        </joint>
        <actuator name="superStructure_joint_motor">
            <hardwareInterface>hardware_interface/EffortJointInterface</hardwareInterface>
            <mechanicalReduction>1</mechanicalReduction>
        </actuator>
    </transmission>
    <transmission name="trans_boom_joint">
        <type>transmission_interface/SimpleTransmission</type>
        <joint name="boom_joint">
            <hardwareInterface>hardware_interface/EffortJointInterface</hardwareInterface>
        </joint>
        <actuator name="boom_joint_motor">
            <hardwareInterface>hardware_interface/EffortJointInterface</hardwareInterface>
            <mechanicalReduction>1</mechanicalReduction>
        </actuator>
    </transmission>
    <transmission name="trans_rope_joint">
        <type>transmission_interface/SimpleTransmission</type>
        <joint name="rope_joint">
            <hardwareInterface>hardware_interface/EffortJointInterface</hardwareInterface>
        </joint>
        <actuator name="rope_joint_motor">
            <hardwareInterface>hardware_interface/EffortJointInterface</hardwareInterface>
            <mechanicalReduction>1</mechanicalReduction>
        </actuator>
    </transmission>
    <transmission name="trans_hook_block_joint">
        <type>transmission_interface/SimpleTransmission</type>
        <joint name="hook_block_joint">
            <hardwareInterface>hardware_interface/EffortJointInterface</hardwareInterface>
        </joint>
        <actuator name="hook_block_joint_motor">
            <hardwareInterface>hardware_interface/EffortJointInterface</hardwareInterface>
            <mechanicalReduction>1</mechanicalReduction>
        </actuator>
    </transmission>
    <transmission name="trans_hook_joint">
        <type>transmission_interface/SimpleTransmission</type>
        <joint name="hook_joint">
            <hardwareInterface>hardware_interface/EffortJointInterface</hardwareInterface>
        </joint>
        <actuator name="hook_joint_motor">
            <hardwareInterface>hardware_interface/EffortJointInterface</hardwareInterface>
            <mechanicalReduction>1</mechanicalReduction>
        </actuator>
    </transmission>
    <gazebo>
        <plugin name="gazebo_ros_control" filename="libgazebo_ros_control.so">
            <robotNamespace>/</robotNamespace>
        </plugin>
    </gazebo>
</robot>

<transmission name="wheel_right_joint_trans">
        <type>transmission_interface/SimpleTransmission</type>
        <joint name="chassis_to_wheel_right_joint" />
        <actuator name="wheel_right_joint_motor">
            <hardwareInterface>EffortJointInterface</hardwareInterface>
            <mechanicalReduction>1</mechanicalReduction>
        </actuator>
    </transmission>
    <!-- lr: left, right -->
    <link name="wheel_left_link">
        <visual>
            <origin rpy="1.57079632679 0  0 " xyz="0 0 0" />
            <geometry>
                <cylinder length="0.12" radius="0.8" />
            </geometry>
            <material name="Black" />
        </visual>
        <collision>
            <origin rpy="1.57079632679 0 0 " xyz="0 0 0" />
            <geometry>
                <cylinder length="0.12" radius="0.8" />
            </geometry>
        </collision>
        <inertial>
            <mass value="2770000.0" />
            <inertia ixx="775600.0" ixy="0" ixz="0" iyy="775600.0" iyz="0" izz="886400.0" />
        </inertial>
        <!-- the crawlerM is placed on the wheels -->
    </link>
    <gazebo reference="wheel_left_link">
        <material>Gazebo/Black</material>
    </gazebo>
    <joint name="chassis_to_wheel_left_joint" type="continuous">
        <parent link="bottom_link" />
        <child link="wheel_left_link" />
        <origin rpy="0 0 0" xyz="0 -4.35 -0.25" />
        <axis rpy="0 0 0" xyz="0 1 0" />
    </joint>
    <!-- Transmission is important to link the joints and the controller -->
    <transmission name="wheel_left_joint_trans">
        <type>transmission_interface/SimpleTransmission</type>
        <joint name="chassis_to_wheel_left_joint" />
        <actuator name="wheel_left_joint_motor">
            <hardwareInterface>EffortJointInterface</hardwareInterface>
            <mechanicalReduction>1</mechanicalReduction>
        </actuator>
    </transmission>
    <!-- superStructure Definitions -->
    <joint name="superStructure_joint" type="continuous">
        <origin rpy="0 0 0" xyz="0 0 1.05" />
        <!-- on the top of slewingRing -->
        <axis rpy="0 0 0" xyz="0 0 1" />
        <limit effort="1000000000000000000000000000" velocity="1.57079632679" />
        <parent link="bottom_link" />
        <child link="superStructure_link" />
    </joint>
    <link name="superStructure_link">
        <inertial>
            <mass value="3300.0" />
            <inertia ixx="23166.0" ixy="0" ixz="0" iyy="24431.0" iyz="0" izz="3047.0" />
        </inertial>
        <visual>
            <origin rpy="0 0 0" xyz="-3.0 0 0.9" />
            <geometry>
                <box size="9.0 2.8 1.8" />
            </geometry>
            <material name="White" />
        </visual>
        <collision>
            <origin rpy="0 0 0 " xyz="-3.0 0 0.9" />
            <geometry>
                <box size="9.0 2.8 1.8" />
            </geometry>
        </collision>
    </link>
    <!-- lr: left, right -->
    <link name="counterWeight_right_link">
        <visual>
            <origin rpy="0 0  0" xyz="0 0 1.55" />
            <geometry>
                <box size="2.495 1.6 3.1" />
            </geometry>
            <material name="red" />
        </visual>
        <collision>
            <origin rpy="0 0 0" xyz="0 0 1.55" />
            <geometry>
                <box size="2.495 1.6 3.1" />
            </geometry>
        </collision>
        <inertial>
            <mass value="6.75" />
            <inertia ixx="8.9072015625" ixy="0" ixz="0" iyy="4.9415765625" iyz="0" izz="6.845625" />
        </inertial>
    </link>
    <gazebo reference="counterWeight_right_link">
        <material>Gazebo/Red</material>
    </gazebo>
    <joint name="superStructure_to_counterWeight_right_joint" type="fixed">
        <parent link="superStructure_link" />
        <child link="counterWeight_right_link" />
        <origin rpy="0 0 0" xyz="-6.75 2.2 0" />
    </joint>
    <!-- lr: left, right -->
    <link name="counterWeight_left_link">
        <visual>
            <origin rpy="0 0  0" xyz="0 0 1.55" />
            <geometry>
                <box size="2.495 1.6 3.1" />
            </geometry>
            <material name="red" />
        </visual>
        <collision>
            <origin rpy="0 0 0" xyz="0 0 1.55" />
            <geometry>
                <box size="2.495 1.6 3.1" />
            </geometry>
        </collision>
        <inertial>
            <mass value="6.75" />
            <inertia ixx="8.9072015625" ixy="0" ixz="0" iyy="4.9415765625" iyz="0" izz="6.845625" />
        </inertial>
    </link>
    <gazebo reference="counterWeight_left_link">
        <material>Gazebo/Red</material>
    </gazebo>
    <joint name="superStructure_to_counterWeight_left_joint" type="fixed">
        <parent link="superStructure_link" />
        <child link="counterWeight_left_link" />
        <origin rpy="0 0 0" xyz="-6.75 -2.2 0" />
    </joint>
    <!-- luffing: boom joint -->
    <joint name="boom_joint" type="revolute">
        <origin rpy="0 0 0" xyz="1.5 0 0.49" />
        <axis xyz="0 -1 0" />
        <limit effort="1000000000000000000000000000" lower="0.6" upper="1.57079632679" velocity="1.57" />
        <parent link="superStructure_link" />
        <child link="boom_link" />
    </joint>
    <link name="boom_link">
        <inertial>
            <mass value="232.0" />
            <inertia ixx="60740.6933333" ixy="0" ixz="0" iyy="60780.9066667" iyz="0" izz="262.933333333" />
        </inertial>
        <visual>
            <plugin filename="libsome_visual_plugin.so" name="some_visual_plugin" />
            <origin rpy="0 0 0" xyz="0 0 0" />
            <geometry>
                <!--<box size="${boomL} ${boomW} ${boomH}" />-->
                <mesh filename="package://crawler_crane_description/meshes/boom.dae" />
            </geometry>
            <material name="red" />
        </visual>
        <collision>
            <origin rpy="0 0 0" xyz="28.0 0 0" />
            <geometry>
                <box size="56.0 2.8 2.4" />
            </geometry>
        </collision>
    </link>
    <joint name="rope_joint" type="revolute">
        <origin rpy="0 0 0" xyz="56.0 0 -1.66" />
        <axis xyz="0 -1 0" />
        <limit effort="1000000000000000000000000000" lower="-3.14159265359" upper="3.14159265359" velocity="1.57" />
        <mimic joint="boom_joint" multiplier="-1.0" offset="0" />
        <parent link="boom_link" />
        <child link="rope_link" />
    </joint>
    <link name="rope_link">
        <inertial>
            <mass value="150.0" />
            <inertia ixx="31250.125" ixy="0" ixz="0" iyy="0.25" iyz="0" izz="31250.125" />
        </inertial>
        <!--hookBlock Mass is placed here -->
        <visual>
            <origin rpy="0 0 0" xyz="0 0 -2.5" />
            <geometry>
                <box size="0.1 0.1 5" />
            </geometry>
        </visual>
    </link>
    <joint name="hook_block_joint" type="prismatic">
        <origin rpy="0 0 0" xyz="0 0 0" />
        <axis xyz="0 0 -1" />
        <limit effort="1000000000000000000000000000" lower="0" upper="84.0" velocity="2.0" />
        <parent link="rope_link" />
        <child link="hook_block_link" />
    </joint>
    <link name="hook_block_link">
        <inertial>
            <mass value="0.03" />
            <inertia ixx="0.027378" ixy="0" ixz="0" iyy="0.027378" iyz="0" izz="0.027378" />
        </inertial>
        <visual>
            <origin rpy="0 0 0" xyz="0 0 0" />
            <geometry>
                <!--<box size="${size} ${size} ${size}" />-->
                <mesh filename="package://crawler_crane_description/meshes/hookblock.dae" />
            </geometry>
            <material name="red" />
        </visual>
        <collision>
            <origin rpy="0 0 0" xyz="0 0 1.17" />
            <geometry>
                <box size="0.7722 2.34 2.34" />
            </geometry>
        </collision>
    </link>
    <joint name="hook_joint" type="revolute">
        <origin rpy="0 0 0" xyz="0 0 -4.11" />
        <axis xyz="0 0 1" />
        <limit effort="1000000000000000000000000000" lower="-3.14159265359" upper="3.14159265359" velocity="1.57" />
        <parent link="hook_block_link" />
        <child link="hook_link" />
    </joint>
    <link name="hook_link">
        <inertial>
            <mass value="0.001" />
            <inertia ixx="0.00052215" ixy="0" ixz="0" iyy="0.000594408333333" iyz="0" izz="0.000594408333333" />
        </inertial>
        <visual>
            <origin rpy="0 0 0" xyz="0 0 0" />
            <geometry>
                <mesh filename="package://crawler_crane_description/meshes/hook.dae" />
            </geometry>
            <material name="red" />
        </visual>
        <collision>
            <origin rpy="0 0 0" xyz="0 0 0.885" />
            <geometry>
                <box size="1.77 2 1.77" />
            </geometry>
        </collision>
    </link>
    <transmission name="tran1">
        <type>transmission_interface/SimpleTransmission</type>
        <joint name="superStructure_joint">
            <hardwareInterface>PositionJointInterface</hardwareInterface>
            <hardwareInterface>VelocityJointInterface</hardwareInterface>
            <hardwareInterface>EffortJointInterface</hardwareInterface>
        </joint>
        <actuator name="motor1">
            <hardwareInterface>VelocityJointInterface</hardwareInterface>
            <mechanicalReduction>1</mechanicalReduction>
        </actuator>
    </transmission>
    <transmission name="tran1">
        <type>transmission_interface/SimpleTransmission</type>
        <joint name="boom_joint">
            <hardwareInterface>PositionJointInterface</hardwareInterface>
            <hardwareInterface>VelocityJointInterface</hardwareInterface>
            <hardwareInterface>EffortJointInterface</hardwareInterface>
        </joint>
        <actuator name="motor1">
            <hardwareInterface>VelocityJointInterface</hardwareInterface>
            <mechanicalReduction>1</mechanicalReduction>
        </actuator>
    </transmission>
    <transmission name="tran1">
        <type>transmission_interface/SimpleTransmission</type>
        <joint name="rope_joint">
            <hardwareInterface>PositionJointInterface</hardwareInterface>
            <hardwareInterface>VelocityJointInterface</hardwareInterface>
            <hardwareInterface>EffortJointInterface</hardwareInterface>
        </joint>
        <actuator name="motor1">
            <hardwareInterface>VelocityJointInterface</hardwareInterface>
            <mechanicalReduction>1</mechanicalReduction>
        </actuator>
    </transmission>
    <transmission name="tran1">
        <type>transmission_interface/SimpleTransmission</type>
        <joint name="hook_block_joint">
            <hardwareInterface>PositionJointInterface</hardwareInterface>
            <hardwareInterface>VelocityJointInterface</hardwareInterface>
            <hardwareInterface>EffortJointInterface</hardwareInterface>
        </joint>
        <actuator name="motor1">
            <hardwareInterface>VelocityJointInterface</hardwareInterface>
            <mechanicalReduction>1</mechanicalReduction>
        </actuator>
    </transmission>
    <transmission name="tran1">
        <type>transmission_interface/SimpleTransmission</type>
        <joint name="hook_joint">
            <hardwareInterface>PositionJointInterface</hardwareInterface>
            <hardwareInterface>VelocityJointInterface</hardwareInterface>
            <hardwareInterface>EffortJointInterface</hardwareInterface>
        </joint>
        <actuator name="motor1">
            <hardwareInterface>VelocityJointInterface</hardwareInterface>
            <mechanicalReduction>1</mechanicalReduction>
        </actuator>
    </transmission>
    <gazebo>
        <!-- Differential drive controller  -->
        <plugin filename="libgazebo_ros_diff_drive.so" name="differential_drive_controller">
            <rosDebugLevel>Debug</rosDebugLevel>
            <publishWheelTF>true</publishWheelTF>
            <robotNamespace>/</robotNamespace>
            <publishTf>1</publishTf>
            <publishWheelJointState>true</publishWheelJointState>
            <alwaysOn>true</alwaysOn>
            <legacyMode>true</legacyMode>
            <updateRate>100.0</updateRate>
            <leftJoint>chassis_to_wheel_left_joint</leftJoint>
            <rightJoint>chassis_to_wheel_right_joint</rightJoint>
            <wheelSeparation>4.35</wheelSeparation>
            <wheelDiameter>1.6</wheelDiameter>
            <broadcastTF>1</broadcastTF>
            <wheelTorque>30000000000000000000000000000000000000000</wheelTorque>
            <wheelAcceleration>1.8</wheelAcceleration>
            <commandTopic>cmd_vel</commandTopic>
            <odometryFrame>odom</odometryFrame>
            <odometryTopic>odom</odometryTopic>
            <robotBaseFrame>base_footprint</robotBaseFrame>
        </plugin>
        <!-- ros_control plugin -->
        <plugin filename="libgazebo_ros_control.so" name="gazebo_ros_control">
            <robotNamespace>/</robotNamespace>
        </plugin>
        <!-- gazebo_mimic_joint plugin -->
        <plugin filename="libroboticsgroup_gazebo_mimic_joint_plugin.so" name="gazebo_mimic_joint">
            <rosDebugLevel>Debug</rosDebugLevel>
            <robotNamespace>/</robotNamespace>
            <joint>boom_joint</joint>
            <mimicJoint>rope_joint</mimicJoint>
            <multiplier>-1</multiplier>
            <maxEffort>1000000000000000000000000000</maxEffort>
        </plugin>
    </gazebo>
    <joint name="velodyne2_base_mount_joint" type="fixed">
        <origin rpy="0 0 0" xyz="4.5 1.68 9.0" />
        <parent link="superStructure_link" />
        <child link="velodyne2_base_link" />
    </joint>
    <link name="velodyne2_base_link">
        <inertial>
            <mass value="1.0" />
            <origin xyz="0 0 0.07212" />
            <inertia ixx="0.002188947025" ixy="0" ixz="0" iyy="0.002188947025" iyz="0" izz="0.00091036445" />
        </inertial>
        <visual>
            <geometry>
                <mesh filename="package://velodyne_description/meshes/HDL32E_base.dae" />
            </geometry>
        </visual>
        <collision>
            <origin rpy="0 0 0" xyz="0 0 0.07212" />
            <geometry>
                <cylinder length="0.14424" radius="0.04267" />
            </geometry>
        </collision>
    </link>
    <joint name="velodyne2_base_scan_joint" type="fixed">
        <origin rpy="0 0 0" xyz="0 0 0.09081" />
        <parent link="velodyne2_base_link" />
        <child link="velodyne2" />
    </joint>
    <link name="velodyne2">
        <inertial>
            <mass value="0.01" />
            <origin xyz="0 0 0" />
            <inertia ixx="1e-7" ixy="0" ixz="0" iyy="1e-7" iyz="0" izz="1e-7" />
        </inertial>
        <visual>
            <origin rpy="0 0 0" xyz="0 0 -0.09081" />
            <geometry>
                <mesh filename="package://velodyne_description/meshes/HDL32E_scan.dae" />
            </geometry>
        </visual>
    </link>
    <!-- Gazebo requires the velodyne_gazebo_plugins package -->
    <gazebo reference="velodyne2">
        <sensor name="velodyne2-HDL32E" type="ray">
            <pose>0 0 0 0 0 0</pose>
            <visualize>false</visualize>
            <update_rate>10</update_rate>
            <ray>
                <scan>
                    <horizontal>
                        <samples>220</samples>
                        <resolution>1</resolution>
                        <min_angle>-3.14159265359</min_angle>
                        <max_angle>3.14159265359</max_angle>
                    </horizontal>
                    <vertical>
                        <samples>32</samples>
                        <resolution>1</resolution>
                        <min_angle>-0.535292481587</min_angle>
                        <max_angle>0.186226631188</max_angle>
                    </vertical>
                </scan>
                <range>
                    <min>0.3</min>
                    <max>131.0</max>
                    <resolution>0.001</resolution>
                </range>
                <noise>
                    <type>gaussian</type>
                    <mean>0.0</mean>
                    <stddev>0.0</stddev>
                </noise>
            </ray>
            <plugin filename="libgazebo_ros_velodyne_laser.so" name="gazebo_ros_laser_controller">
                <topicName>/velodyne_points2</topicName>
                <frameName>velodyne2</frameName>
                <min_range>0.9</min_range>
                <max_range>130.0</max_range>
                <gaussianNoise>0.008</gaussianNoise>
            </plugin>
        </sensor>
    </gazebo>
    <transmission name="trans_chassis_to_wheel_right_joint">
        <type>transmission_interface/SimpleTransmission</type>
        <joint name="chassis_to_wheel_right_joint">
            <hardwareInterface>hardware_interface/EffortJointInterface</hardwareInterface>
        </joint>
        <actuator name="chassis_to_wheel_right_joint_motor">
            <hardwareInterface>hardware_interface/EffortJointInterface</hardwareInterface>
            <mechanicalReduction>1</mechanicalReduction>
        </actuator>
    </transmission>
    <transmission name="trans_chassis_to_wheel_left_joint">
        <type>transmission_interface/SimpleTransmission</type>
        <joint name="chassis_to_wheel_left_joint">
            <hardwareInterface>hardware_interface/EffortJointInterface</hardwareInterface>
        </joint>
        <actuator name="chassis_to_wheel_left_joint_motor">
            <hardwareInterface>hardware_interface/EffortJointInterface</hardwareInterface>
            <mechanicalReduction>1</mechanicalReduction>
        </actuator>
    </transmission>
    <transmission name="trans_superStructure_joint">
        <type>transmission_interface/SimpleTransmission</type>
        <joint name="superStructure_joint">
            <hardwareInterface>hardware_interface/EffortJointInterface</hardwareInterface>
        </joint>
        <actuator name="superStructure_joint_motor">
            <hardwareInterface>hardware_interface/EffortJointInterface</hardwareInterface>
            <mechanicalReduction>1</mechanicalReduction>
        </actuator>
    </transmission>
    <transmission name="trans_boom_joint">
        <type>transmission_interface/SimpleTransmission</type>
        <joint name="boom_joint">
            <hardwareInterface>hardware_interface/EffortJointInterface</hardwareInterface>
        </joint>
        <actuator name="boom_joint_motor">
            <hardwareInterface>hardware_interface/EffortJointInterface</hardwareInterface>
            <mechanicalReduction>1</mechanicalReduction>
        </actuator>
    </transmission>
    <transmission name="trans_rope_joint">
        <type>transmission_interface/SimpleTransmission</type>
        <joint name="rope_joint">
            <hardwareInterface>hardware_interface/EffortJointInterface</hardwareInterface>
        </joint>
        <actuator name="rope_joint_motor">
            <hardwareInterface>hardware_interface/EffortJointInterface</hardwareInterface>
            <mechanicalReduction>1</mechanicalReduction>
        </actuator>
    </transmission>
    <transmission name="trans_hook_block_joint">
        <type>transmission_interface/SimpleTransmission</type>
        <joint name="hook_block_joint">
            <hardwareInterface>hardware_interface/EffortJointInterface</hardwareInterface>
        </joint>
        <actuator name="hook_block_joint_motor">
            <hardwareInterface>hardware_interface/EffortJointInterface</hardwareInterface>
            <mechanicalReduction>1</mechanicalReduction>
        </actuator>
    </transmission>
    <transmission name="trans_hook_joint">
        <type>transmission_interface/SimpleTransmission</type>
        <joint name="hook_joint">
            <hardwareInterface>hardware_interface/EffortJointInterface</hardwareInterface>
        </joint>
        <actuator name="hook_joint_motor">
            <hardwareInterface>hardware_interface/EffortJointInterface</hardwareInterface>
            <mechanicalReduction>1</mechanicalReduction>
        </actuator>
    </transmission>
    <gazebo>
        <plugin name="gazebo_ros_control" filename="libgazebo_ros_control.so">
            <robotNamespace>/</robotNamespace>
        </plugin>
    </gazebo>
</robot>
